id: PYSEC-0000-CVE-2022-42731
details: mfa/FIDO2.py in django-mfa2 before 2.5.1 and 2.6.x before 2.6.1 allows a
  replay attack that could be used to register another device for a user. The device
  registration challenge is not invalidated after usage.
affected:
- package:
    name: django-mfa2
    ecosystem: PyPI
    purl: pkg:pypi/django-mfa2
  ranges:
  - type: ECOSYSTEM
    events:
    - introduced: "0"
    - fixed: 2.5.1
    - introduced: 2.6.0
    - fixed: 2.6.1
references:
- type: WEB
  url: https://github.com/mkalioby/django-mfa2/releases/tag/v2.6.1-release
- type: WEB
  url: https://github.com/mkalioby/django-mfa2/releases/tag/v2.5.1-release
- type: EVIDENCE
  url: https://github.com/mkalioby/django-mfa2/blob/0936ea253354dd95cb127f09d0efa31324caef27/mfa/FIDO2.py#L58
- type: WEB
  url: https://github.com/mkalioby/django-mfa2/blob/0936ea253354dd95cb127f09d0efa31324caef27/mfa/FIDO2.py#L58
aliases:
- CVE-2022-42731
modified: "2022-10-11T19:05:00Z"
published: "2022-10-11T14:15:00Z"
