{
    "GSD": {
        "alias": "CVE-2021-28861",
        "description": "Python 3.x through 3.10 has an open redirection vulnerability in lib/http/server.py due to no protection against multiple (/) at the beginning of URI path which may leads to information disclosure.",
        "id": "GSD-2021-28861"
    },
    "namespaces": {
        "cve.org": {
            "CVE_data_meta": {
                "ASSIGNER": "cve@mitre.org",
                "ID": "CVE-2021-28861",
                "STATE": "PUBLIC"
            },
            "affects": {
                "vendor": {
                    "vendor_data": [
                        {
                            "product": {
                                "product_data": [
                                    {
                                        "product_name": "n/a",
                                        "version": {
                                            "version_data": [
                                                {
                                                    "version_value": "n/a"
                                                }
                                            ]
                                        }
                                    }
                                ]
                            },
                            "vendor_name": "n/a"
                        }
                    ]
                }
            },
            "data_format": "MITRE",
            "data_type": "CVE",
            "data_version": "4.0",
            "description": {
                "description_data": [
                    {
                        "lang": "eng",
                        "value": "Python 3.x through 3.10 has an open redirection vulnerability in lib/http/server.py due to no protection against multiple (/) at the beginning of URI path which may leads to information disclosure."
                    }
                ]
            },
            "problemtype": {
                "problemtype_data": [
                    {
                        "description": [
                            {
                                "lang": "eng",
                                "value": "n/a"
                            }
                        ]
                    }
                ]
            },
            "references": {
                "reference_data": [
                    {
                        "name": "https://bugs.python.org/issue43223",
                        "refsource": "MISC",
                        "url": "https://bugs.python.org/issue43223"
                    },
                    {
                        "name": "https://github.com/python/cpython/pull/93879",
                        "refsource": "MISC",
                        "url": "https://github.com/python/cpython/pull/93879"
                    },
                    {
                        "name": "https://github.com/python/cpython/pull/24848",
                        "refsource": "MISC",
                        "url": "https://github.com/python/cpython/pull/24848"
                    }
                ]
            }
        },
        "nvd.nist.gov": {
            "configurations": {
                "CVE_data_version": "4.0",
                "nodes": []
            },
            "cve": {
                "CVE_data_meta": {
                    "ASSIGNER": "cve@mitre.org",
                    "ID": "CVE-2021-28861"
                },
                "data_format": "MITRE",
                "data_type": "CVE",
                "data_version": "4.0",
                "description": {
                    "description_data": [
                        {
                            "lang": "en",
                            "value": "Python 3.x through 3.10 has an open redirection vulnerability in lib/http/server.py due to no protection against multiple (/) at the beginning of URI path which may leads to information disclosure."
                        }
                    ]
                },
                "problemtype": {
                    "problemtype_data": [
                        {
                            "description": []
                        }
                    ]
                },
                "references": {
                    "reference_data": [
                        {
                            "name": "https://github.com/python/cpython/pull/93879",
                            "refsource": "MISC",
                            "tags": [],
                            "url": "https://github.com/python/cpython/pull/93879"
                        },
                        {
                            "name": "https://bugs.python.org/issue43223",
                            "refsource": "MISC",
                            "tags": [],
                            "url": "https://bugs.python.org/issue43223"
                        },
                        {
                            "name": "https://github.com/python/cpython/pull/24848",
                            "refsource": "MISC",
                            "tags": [],
                            "url": "https://github.com/python/cpython/pull/24848"
                        }
                    ]
                }
            },
            "impact": {},
            "lastModifiedDate": "2022-08-23T01:15Z",
            "publishedDate": "2022-08-23T01:15Z"
        }
    }
}